Workbook

Sheet Cover
C5: DCF Valuation Engine
C6: Professional business valuation model
C7: Saad Rashid, CFA
C8: =TODAY()
C9: Confidential — For Discussion Purposes Only

Sheet Assumptions
B2: Model assumptions
B4: Input
B6: Company Name | C6: CloudMetrics Inc.
B8: Base Revenue | C8: 2
B9: Revenue Growth Y1 - Y5 | C9: 0.35
B10: Terminal Growth Rate | C10: 0.035
B11: EBITDA Margin | C11: 0.18
B12: D&A as % of Revenue | C12: 0.05
B13: CapEx as % of Revenue | C13: 0.05
B14: Change in WC% | C14: 0.08
B15: Tax Rate | C15: 0.25
B16: WACC | C16: 0.12
B17: Net Debt | C17: 2.5
B18: Shares Outstanding | C18: 10
B20: Yellow cells are inputs — change these for your company

Sheet DCF Model
B2: DCF Model — CloudMetrics Inc.
B4: Line Item | C4: Year 1 | D4: Year 2 | E4: Year 3 | F4: Year 4 | G4: Year 5
B5: Revenue | C5: =Assumptions!$C$8*(1+Assumptions!$C$9) | D5: =C5*(1+Assumptions!$C$9) | E5: =D5*(1+Assumptions!$C$9) | F5: =E5*(1+Assumptions!$C$9) | G5: =F5*(1+Assumptions!$C$9)
B6: EBITDA | C6: =C5*Assumptions!$C$11 | D6: =D5*Assumptions!$C$11 | E6: =E5*Assumptions!$C$11 | F6: =F5*Assumptions!$C$11 | G6: =G5*Assumptions!$C$11
B7: D&A | C7: =C5*Assumptions!$C$12 | D7: =D5*Assumptions!$C$12 | E7: =E5*Assumptions!$C$12 | F7: =F5*Assumptions!$C$12 | G7: =G5*Assumptions!$C$12
B8: EBIT | C8: =C6-C7 | D8: =D6-D7 | E8: =E6-E7 | F8: =F6-F7 | G8: =G6-G7
B9: NOPAT | C9: =C8*(1-Assumptions!$C$15) | D9: =D8*(1-Assumptions!$C$15) | E9: =E8*(1-Assumptions!$C$15) | F9: =F8*(1-Assumptions!$C$15) | G9: =G8*(1-Assumptions!$C$15)
B10: Add back D&A | C10: =C7 | D10: =D7 | E10: =E7 | F10: =F7 | G10: =G7
B11: Less Capex | C11: =C5*Assumptions!$C$13 | D11: =D5*Assumptions!$C$13 | E11: =E5*Assumptions!$C$13 | F11: =F5*Assumptions!$C$13 | G11: =G5*Assumptions!$C$13
B12: Less Change in WC | C12: =C5*Assumptions!$C$14 | D12: =D5*Assumptions!$C$14 | E12: =E5*Assumptions!$C$14 | F12: =F5*Assumptions!$C$14 | G12: =G5*Assumptions!$C$14
B13: Free Cash Flow (FCF) | C13: =C9+C10-C11-C12 | D13: =D9+D10-D11-D12 | E13: =E9+E10-E11-E12 | F13: =F9+F10-F11-F12 | G13: =G9+G10-G11-G12
B15: Valuation
B17: Terminal Value | C17: =G13*(1+Assumptions!$C$10)/(Assumptions!$C$16-Assumptions!$C$10)
B18: PV of FCF year 1 | C18: =C13/(1+Assumptions!$C$16)^1
B19: PV of FCF year 2 | C19: =D13/(1+Assumptions!$C$16)^1
B20: PV of FCF year 3 | C20: =E13/(1+Assumptions!$C$16)^1
B21: PV of FCF year 4 | C21: =F13/(1+Assumptions!$C$16)^1
B22: PV of FCF year 5
B23: PV of terminal value
B25: Enterprise Value
B26: Less net debt
B27: Equiyt Value
B28: Shares Outstanding
B29: Value per share

Sheet Scenarios
B2: Scenario Analysis — CloudMetrics Inc.
C4: Bear Case | D4: Base Case | E4: Bull Case
B5: Assumptions
B6: Base Revenue ($mm) | C6: 2 | D6: 2 | E6: 2
B7: Revenue Growth | C7: 0.2 | D7: 0.35 | E7: 0.5
B8: EBITDA Margin | C8: 0.12 | D8: 0.18 | E8: 0.25
B9: D&A % of Revenue | C9: 0.05 | D9: 0.05 | E9: 0.05
B10: CapEx % of Revenue | C10: 0.05 | D10: 0.05 | E10: 0.05
B11: Change in WC % | C11: 0.08 | D11: 0.08 | E11: 0.08
B12: Tax Rate | C12: 0.25 | D12: 0.25 | E12: 0.25
B13: WACC | C13: 0.14 | D13: 0.12 | E13: 0.1
B14: Terminal Growth Rate | C14: 0.025 | D14: 0.035 | E14: 0.04
B15: Net Debt ($mm) | C15: 2.5 | D15: 2.5 | E15: 2.5
B16: Shares Outstanding (mm) | C16: 10 | D16: 10 | E16: 10
B18: Revenue Projections ($mm)
C19: Bear Case | D19: Base Case | E19: Bull Case
B20: Year 1 | C20: =C$6*(1+C$7)^1 | D20: =D$6*(1+D$7)^1 | E20: =E$6*(1+E$7)^1
B21: Year 2 | C21: =C$6*(1+C$7)^2 | D21: =D$6*(1+D$7)^2 | E21: =E$6*(1+E$7)^2
B22: Year 3 | C22: =C$6*(1+C$7)^3 | D22: =D$6*(1+D$7)^3 | E22: =E$6*(1+E$7)^3
B23: Year 4 | C23: =C$6*(1+C$7)^4 | D23: =D$6*(1+D$7)^4 | E23: =E$6*(1+E$7)^4
B24: Year 5 | C24: =C$6*(1+C$7)^5 | D24: =D$6*(1+D$7)^5 | E24: =E$6*(1+E$7)^5
B26: Valuation
C27: Bear Case | D27: Base Case | E27: Bull Case
B28: Year 5 Revenue ($mm) | C28: =C24 | D28: =D24 | E28: =E24
B29: Year 5 EBITDA ($mm) | C29: =C28*C$8 | D29: =D28*D$8 | E29: =E28*E$8
B30: Year 5 EBIT ($mm) | C30: =C29-C28*C$9 | D30: =D29-D28*D$9 | E30: =E29-E28*E$9
B31: Year 5 NOPAT ($mm) | C31: =C30*(1-C$12) | D31: =D30*(1-D$12) | E31: =E30*(1-E$12)
B32: Add: D&A ($mm) | C32: =C28*C$9 | D32: =D28*D$9 | E32: =E28*E$9
B33: Less: CapEx ($mm) | C33: =C28*C$10 | D33: =D28*D$10 | E33: =E28*E$10
B34: Less: Change in WC ($mm) | C34: =C28*C$11 | D34: =D28*D$11 | E34: =E28*E$11
B35: Year 5 FCF ($mm) | C35: =C31+C32-C33-C34 | D35: =D31+D32-D33-D34 | E35: =E31+E32-E33-E34
B37: Terminal Value ($mm) | C37: =C35*(1+C$14)/(C$13-C$14) | D37: =D35*(1+D$14)/(D$13-D$14) | E37: =E35*(1+E$14)/(E$13-E$14)
B38: PV of FCF Year 1 ($mm) | C38: =((C$6*(1+C$7)^1*C$8-C$6*(1+C$7)^1*C$9)*(1-C$12)+C$6*(1+C$7)^1*C$9-C$6*(1+C$7)^1*C$10-C$6*(1+C$7)^1*C$11)/(1+C$13)^1 | D38: =((D$6*(1+D$7)^1*D$8-D$6*(1+D$7)^1*D$9)*(1-D$12)+D$6*(1+D$7)^1*D$9-D$6*(1+D$7)^1*D$10-D$6*(1+D$7)^1*D$11)/(1+D$13)^1 | E38: =((E$6*(1+E$7)^1*E$8-E$6*(1+E$7)^1*E$9)*(1-E$12)+E$6*(1+E$7)^1*E$9-E$6*(1+E$7)^1*E$10-E$6*(1+E$7)^1*E$11)/(1+E$13)^1
B39: PV of FCF Year 2 ($mm) | C39: =((C$6*(1+C$7)^2*C$8-C$6*(1+C$7)^2*C$9)*(1-C$12)+C$6*(1+C$7)^2*C$9-C$6*(1+C$7)^2*C$10-C$6*(1+C$7)^2*C$11)/(1+C$13)^2 | D39: =((D$6*(1+D$7)^2*D$8-D$6*(1+D$7)^2*D$9)*(1-D$12)+D$6*(1+D$7)^2*D$9-D$6*(1+D$7)^2*D$10-D$6*(1+D$7)^2*D$11)/(1+D$13)^2 | E39: =((E$6*(1+E$7)^2*E$8-E$6*(1+E$7)^2*E$9)*(1-E$12)+E$6*(1+E$7)^2*E$9-E$6*(1+E$7)^2*E$10-E$6*(1+E$7)^2*E$11)/(1+E$13)^2
B40: PV of FCF Year 3 ($mm) | C40: =((C$6*(1+C$7)^3*C$8-C$6*(1+C$7)^3*C$9)*(1-C$12)+C$6*(1+C$7)^3*C$9-C$6*(1+C$7)^3*C$10-C$6*(1+C$7)^3*C$11)/(1+C$13)^3 | D40: =((D$6*(1+D$7)^3*D$8-D$6*(1+D$7)^3*D$9)*(1-D$12)+D$6*(1+D$7)^3*D$9-D$6*(1+D$7)^3*D$10-D$6*(1+D$7)^3*D$11)/(1+D$13)^3 | E40: =((E$6*(1+E$7)^3*E$8-E$6*(1+E$7)^3*E$9)*(1-E$12)+E$6*(1+E$7)^3*E$9-E$6*(1+E$7)^3*E$10-E$6*(1+E$7)^3*E$11)/(1+E$13)^3
B41: PV of FCF Year 4 ($mm) | C41: =((C$6*(1+C$7)^4*C$8-C$6*(1+C$7)^4*C$9)*(1-C$12)+C$6*(1+C$7)^4*C$9-C$6*(1+C$7)^4*C$10-C$6*(1+C$7)^4*C$11)/(1+C$13)^4 | D41: =((D$6*(1+D$7)^4*D$8-D$6*(1+D$7)^4*D$9)*(1-D$12)+D$6*(1+D$7)^4*D$9-D$6*(1+D$7)^4*D$10-D$6*(1+D$7)^4*D$11)/(1+D$13)^4 | E41: =((E$6*(1+E$7)^4*E$8-E$6*(1+E$7)^4*E$9)*(1-E$12)+E$6*(1+E$7)^4*E$9-E$6*(1+E$7)^4*E$10-E$6*(1+E$7)^4*E$11)/(1+E$13)^4
B42: PV of FCF Year 5 ($mm) | C42: =C35/(1+C$13)^5 | D42: =D35/(1+D$13)^5 | E42: =E35/(1+E$13)^5
B43: PV of Terminal Value ($mm) | C43: =C37/(1+C$13)^5 | D43: =D37/(1+D$13)^5 | E43: =E37/(1+E$13)^5
B45: Enterprise Value ($mm) | C45: =SUM(C38:C43) | D45: =SUM(D38:D43) | E45: =SUM(E38:E43)
B46: Less: Net Debt ($mm) | C46: =C$15 | D46: =D$15 | E46: =E$15
...

Sheet Sensitivity
B2: Sensitivity Analysis: Enterprise Value (EUR M)
B4: Year 5 FCF ($mm) | C4: 0.157
B6: WACC \ Terminal Growth | C6: 0.015 | D6: 0.02 | E6: 0.025 | F6: 0.03 | G6: 0.035 | H6: 0.04 | I6: 0.045 | J6: 0.05 | K6: 0.055
B7: 0.08 | C7: =$C$4*(1+C$6)/($B7-C$6)/(1+$B7)^5 | D7: =$C$4*(1+D$6)/($B7-D$6)/(1+$B7)^5 | E7: =$C$4*(1+E$6)/($B7-E$6)/(1+$B7)^5 | F7: =$C$4*(1+F$6)/($B7-F$6)/(1+$B7)^5 | G7: =$C$4*(1+G$6)/($B7-G$6)/(1+$B7)^5 | H7: =$C$4*(1+H$6)/($B7-H$6)/(1+$B7)^5 | I7: =$C$4*(1+I$6)/($B7-I$6)/(1+$B7)^5 | J7: =$C$4*(1+J$6)/($B7-J$6)/(1+$B7)^5 | K7: =$C$4*(1+K$6)/($B7-K$6)/(1+$B7)^5
B8: 0.09 | C8: =$C$4*(1+C$6)/($B8-C$6)/(1+$B8)^5 | D8: =$C$4*(1+D$6)/($B8-D$6)/(1+$B8)^5 | E8: =$C$4*(1+E$6)/($B8-E$6)/(1+$B8)^5 | F8: =$C$4*(1+F$6)/($B8-F$6)/(1+$B8)^5 | G8: =$C$4*(1+G$6)/($B8-G$6)/(1+$B8)^5 | H8: =$C$4*(1+H$6)/($B8-H$6)/(1+$B8)^5 | I8: =$C$4*(1+I$6)/($B8-I$6)/(1+$B8)^5 | J8: =$C$4*(1+J$6)/($B8-J$6)/(1+$B8)^5 | K8: =$C$4*(1+K$6)/($B8-K$6)/(1+$B8)^5
B9: 0.1 | C9: =$C$4*(1+C$6)/($B9-C$6)/(1+$B9)^5 | D9: =$C$4*(1+D$6)/($B9-D$6)/(1+$B9)^5 | E9: =$C$4*(1+E$6)/($B9-E$6)/(1+$B9)^5 | F9: =$C$4*(1+F$6)/($B9-F$6)/(1+$B9)^5 | G9: =$C$4*(1+G$6)/($B9-G$6)/(1+$B9)^5 | H9: =$C$4*(1+H$6)/($B9-H$6)/(1+$B9)^5 | I9: =$C$4*(1+I$6)/($B9-I$6)/(1+$B9)^5 | J9: =$C$4*(1+J$6)/($B9-J$6)/(1+$B9)^5 | K9: =$C$4*(1+K$6)/($B9-K$6)/(1+$B9)^5
B10: 0.11 | C10: =$C$4*(1+C$6)/($B10-C$6)/(1+$B10)^5 | D10: =$C$4*(1+D$6)/($B10-D$6)/(1+$B10)^5 | E10: =$C$4*(1+E$6)/($B10-E$6)/(1+$B10)^5 | F10: =$C$4*(1+F$6)/($B10-F$6)/(1+$B10)^5 | G10: =$C$4*(1+G$6)/($B10-G$6)/(1+$B10)^5 | H10: =$C$4*(1+H$6)/($B10-H$6)/(1+$B10)^5 | I10: =$C$4*(1+I$6)/($B10-I$6)/(1+$B10)^5 | J10: =$C$4*(1+J$6)/($B10-J$6)/(1+$B10)^5 | K10: =$C$4*(1+K$6)/($B10-K$6)/(1+$B10)^5
B11: 0.12 | C11: =$C$4*(1+C$6)/($B11-C$6)/(1+$B11)^5 | D11: =$C$4*(1+D$6)/($B11-D$6)/(1+$B11)^5 | E11: =$C$4*(1+E$6)/($B11-E$6)/(1+$B11)^5 | F11: =$C$4*(1+F$6)/($B11-F$6)/(1+$B11)^5 | G11: =$C$4*(1+G$6)/($B11-G$6)/(1+$B11)^5 | H11: =$C$4*(1+H$6)/($B11-H$6)/(1+$B11)^5 | I11: =$C$4*(1+I$6)/($B11-I$6)/(1+$B11)^5 | J11: =$C$4*(1+J$6)/($B11-J$6)/(1+$B11)^5 | K11: =$C$4*(1+K$6)/($B11-K$6)/(1+$B11)^5
B12: 0.13 | C12: =$C$4*(1+C$6)/($B12-C$6)/(1+$B12)^5 | D12: =$C$4*(1+D$6)/($B12-D$6)/(1+$B12)^5 | E12: =$C$4*(1+E$6)/($B12-E$6)/(1+$B12)^5 | F12: =$C$4*(1+F$6)/($B12-F$6)/(1+$B12)^5 | G12: =$C$4*(1+G$6)/($B12-G$6)/(1+$B12)^5 | H12: =$C$4*(1+H$6)/($B12-H$6)/(1+$B12)^5 | I12: =$C$4*(1+I$6)/($B12-I$6)/(1+$B12)^5 | J12: =$C$4*(1+J$6)/($B12-J$6)/(1+$B12)^5 | K12: =$C$4*(1+K$6)/($B12-K$6)/(1+$B12)^5
B13: 0.14 | C13: =$C$4*(1+C$6)/($B13-C$6)/(1+$B13)^5 | D13: =$C$4*(1+D$6)/($B13-D$6)/(1+$B13)^5 | E13: =$C$4*(1+E$6)/($B13-E$6)/(1+$B13)^5 | F13: =$C$4*(1+F$6)/($B13-F$6)/(1+$B13)^5 | G13: =$C$4*(1+G$6)/($B13-G$6)/(1+$B13)^5 | H13: =$C$4*(1+H$6)/($B13-H$6)/(1+$B13)^5 | I13: =$C$4*(1+I$6)/($B13-I$6)/(1+$B13)^5 | J13: =$C$4*(1+J$6)/($B13-J$6)/(1+$B13)^5 | K13: =$C$4*(1+K$6)/($B13-K$6)/(1+$B13)^5
B14: 0.15 | C14: =$C$4*(1+C$6)/($B14-C$6)/(1+$B14)^5 | D14: =$C$4*(1+D$6)/($B14-D$6)/(1+$B14)^5 | E14: =$C$4*(1+E$6)/($B14-E$6)/(1+$B14)^5 | F14: =$C$4*(1+F$6)/($B14-F$6)/(1+$B14)^5 | G14: =$C$4*(1+G$6)/($B14-G$6)/(1+$B14)^5 | H14: =$C$4*(1+H$6)/($B14-H$6)/(1+$B14)^5 | I14: =$C$4*(1+I$6)/($B14-I$6)/(1+$B14)^5 | J14: =$C$4*(1+J$6)/($B14-J$6)/(1+$B14)^5 | K14: =$C$4*(1+K$6)/($B14-K$6)/(1+$B14)^5
B15: 0.16 | C15: =$C$4*(1+C$6)/($B15-C$6)/(1+$B15)^5 | D15: =$C$4*(1+D$6)/($B15-D$6)/(1+$B15)^5 | E15: =$C$4*(1+E$6)/($B15-E$6)/(1+$B15)^5 | F15: =$C$4*(1+F$6)/($B15-F$6)/(1+$B15)^5 | G15: =$C$4*(1+G$6)/($B15-G$6)/(1+$B15)^5 | H15: =$C$4*(1+H$6)/($B15-H$6)/(1+$B15)^5 | I15: =$C$4*(1+I$6)/($B15-I$6)/(1+$B15)^5 | J15: =$C$4*(1+J$6)/($B15-J$6)/(1+$B15)^5 | K15: =$C$4*(1+K$6)/($B15-K$6)/(1+$B15)^5

Sheet Output Summary
B2: EQUITY RESEARCH | VALUATION TEARSHEET
B4: CloudMetrics Inc. | D4: Model Date: | E4: =TODAY()
B5: SaaS / Technology | D5: Prepared by: | E5: Saad Rashid, CFA
B8: VALUATION SUMMARY
B10: Bear Case | C10: Base Case | D10: Bull Case | E10: Enterprise Value
B11: 1.2 | C11: 1.9 | D11: 3.1 | E11: Range
B12: EUR M | C12: EUR M | D12: EUR M | E12: 1.2 – 3.1 EUR M
B14: KEY ASSUMPTIONS
B15: Metric | C15: Value | D15: Source
B16: WACC | C16: =Assumptions!C16 | D16: Assumptions Tab
B17: Terminal Growth Rate | C17: =Assumptions!C10 | D17: Assumptions Tab
B18: Revenue CAGR | C18: =Assumptions!C9 | D18: Assumptions Tab
B19: EBITDA Margin | C19: =Assumptions!C11 | D19: Assumptions Tab
B20: Projection Period | C20: 5 Years | D20: Model Structure
B22: COMPARABLE BENCHMARKS
B23: Company | C23: EV / EBITDA | D23: EV / Revenue | E23: P / E
B25: COMPARABLE BENCHMARKS
B26: Company | C26: EV / EBITDA | D26: EV / Revenue | E26: P / E
B30: Mean
B31: Median
B33: ⚙ Live data populated by Python script
B35: DISCLAIMER
B36: This valuation model is for illustrative purposes only. All projections are based on management estimates and publicly available information. This does not constitute investment advice.

Sheet Comps
A1: Comparable Company Analysis | Pulled: 28 Apr 2026, 18:25
A3: Company | B3: Ticker | C3: Market Cap ($B) | D3: EV ($B) | E3: Revenue ($B) | F3: EBITDA ($B) | G3: EV/EBITDA (x) | H3: EV/Revenue (x) | I3: P/E (x) | J3: Price ($)
A4: Apple | B4: AAPL | C4: 3955 | D4: 3978.6 | E4: 435.6 | F4: 152.9 | G4: 26 | H4: 9.1 | I4: 33.6 | J4: 269.41
A5: Microsoft | B5: MSFT | C5: 3182.4 | D5: 3216.2 | E5: 305.5 | F5: 175.3 | G5: 18.4 | H5: 10.5 | I5: 26.7 | J5: 428.16
A6: Alphabet | B6: GOOGL | C6: 4225 | D6: 4165.1 | E6: 402.8 | F6: 150.2 | G6: 27.7 | H6: 10.3 | I6: 32 | J6: 349.25
A7: Meta | B7: META | C7: 1698.5 | D7: 1702 | E7: 201 | F7: 101.9 | G7: 16.7 | H7: 8.5 | I7: 28.1 | J7: 669.12
A8: Amazon | B8: AMZN | C8: 2797.2 | D8: 2852.7 | E8: 716.9 | F8: 145.7 | G8: 19.6 | H8: 4 | I8: 36 | J8: 260.1
A9: Mean | B9: — | G9: 21.7 | H9: 8.5 | I9: 31.3
A10: Median | B10: — | G10: 19.6 | H10: 9.1 | I10: 32
A11: Min | B11: — | G11: 16.7 | H11: 4 | I11: 26.7
A12: Max | B12: — | G12: 27.7 | H12: 10.5 | I12: 36
